[
remote_reference
.
py
]
expected
:
ERROR
